Workbook
Name \a: #REF!
Name \a: #REF!
Name \a: #REF!
Name \a: #REF!
Name \I: #REF!
Name \P: #REF!
Name _______________________________PG8: #REF!
Name ______________________________PG8: #REF!
Name _____________________________PG8: #REF!
Name _____________________________PG8: #REF!
Name _____________________________PG8: #REF!
Name ____________________________PG8: #REF!
Name ____________________________PG8: #REF!
Name ____________________________PG8: #REF!
Name ___________________________PG8: #REF!
Name ___________________________PG8: #REF!
Name ___________________________PG8: #REF!
Name __________________________PG8: #REF!
Name __________________________PG8: #REF!
Name __________________________PG8: #REF!
Name _________________________PG8: #REF!
Name _________________________PG8: #REF!
Name _________________________PG8: #REF!
Name ________________________PG8: #REF!
Name ________________________PG8: #REF!
Name ________________________PG8: #REF!
Name _______________________PG8: #REF!
Name _______________________PG8: #REF!
Name _______________________PG8: #REF!
Name ______________________PG8: #REF!
Name ______________________PG8: #REF!
Name ______________________PG8: #REF!
Name _____________________PG8: #REF!
Name _____________________PG8: #REF!
Name _____________________PG8: #REF!
Name ____________________PG8: #REF!
Name ____________________PG8: #REF!
Name ____________________PG8: #REF!
Name ___________________PG8: #REF!
Name ___________________PG8: #REF!
Name ___________________PG8: #REF!
Name __________________PG8: #REF!
Name __________________PG8: #REF!
Name __________________PG8: #REF!
Name _________________PG8: #REF!
Name _________________PG8: #REF!
Name _________________PG8: #REF!
Name ________________PG8: #REF!
Name ________________PG8: #REF!
Name ________________PG8: #REF!
Name _______________PG8: #REF!
Name _______________PG8: #REF!
Name _______________PG8: #REF!
Name ______________PG8: #REF!
Name ______________PG8: #REF!
Name ______________PG8: #REF!
Name _____________PG8: #REF!
Name _____________PG8: #REF!
Name _____________PG8: #REF!
Name ____________PG8: #REF!

Sheet PT_CRUDE_H
C2: Petroleum Planning & Analysis Cell
A8: Period : Since 1998 -99 | B8: ('000 Metric Tonnes)
A9: Crude Oil Processed by Refineries
A10: OIL COMPANIES | B10: 1998-99 | C10: 1999-00 | D10: 2000-01 | E10: 2001-02 | F10: 2002-03 | G10: 2003-04 | H10: 2004-05 | I10: 2005-06 | J10: 2006-07 | K10: 2007-08 | L10: 2008-09 | M10: 2009-10 | N10: 2010-11 | O10: 2011-12 | P10: 2012-13 | Q10: 2013-14 | R10: 2014-15 | S10: 2015-16 | T10: 2016-17 | U10: 2017-18 | V10: 2018-19 | W10: 2019-20 | X10: 2020-21 | Y10: 2021-22 | Z10: 2022-23 | AA10: 2023-24 | AB10: 2024-25 | AC10: 2025-26 (P) | AD10: 2026-27 (Till June) (P)
A11: Indian Oil Corporation Ltd. (IOCL)
A12: IOCL-KOYALI, GUJARAT | B12: 10935 | C12: 11109 | D12: 12003 | E12: 11695.788 | F12: 12431.904 | G12: 12758 | H12: 11697.84 | I12: 11540.314 | J12: 12953 | K12: 13714.149 | L12: 13852.052 | M12: 13205.533 | N12: 13561.066 | O12: 14253.08 | P12: 13154.948 | Q12: 12960.077 | R12: 13285.436 | S12: 13819.914 | T12: 13994.392 | U12: 13811.318 | V12: 13504.918 | W12: =+'Monthwise 2019-20'!N12 -> 13074.744 | X12: =+'Monthwise 2020-21'!N12 -> 11603.051 | Y12: 13474.106 | Z12: 15566.899 | AA12: 15202.188 | AB12: 15283.046 | AC12: 13202.134 | AD12: 4327.514
A13: IOCL-MATHURA, UTTAR PRADESH | B13: 8909 | C13: 8125 | D13: 7133 | E13: 8030.827 | F13: 8206.525 | G13: 8249 | H13: 6387.011 | I13: 7937.564 | J13: 8883 | K13: 8033.297 | L13: 8600.966 | M13: 8107.332 | N13: 8879.961 | O13: 8202.175 | P13: 8560.887 | Q13: 6640.674 | R13: 8515.432 | S13: 8860.281 | T13: 9229.999 | U13: 9240.208 | V13: 9736.536 | W13: =+'Monthwise 2019-20'!N14 -> 8948.039 | X13: =+'Monthwise 2020-21'!N14 -> 8925.795 | Y13: 9122.844 | Z13: 9573.012 | AA13: 9190.528 | AB13: 8053.82 | AC13: 10049.509 | AD13: 2189.034
A14: IOCL-PANIPAT, HARYANA | B14: 2208 | C14: 4153 | D14: 5707 | E14: 5822.3 | F14: 6101.26 | G14: 6338 | H14: 6386.77 | I14: 6506.678 | J14: 9435 | K14: 12820.96 | L14: 13069.867 | M14: 13614.547 | N14: 13660.476 | O14: 15495.88 | P14: 15126.03 | Q14: 15097.714 | R14: 14191.003 | S14: 15282.368 | T14: 15638.035 | U14: 15654.196 | V14: 15280.517 | W14: =+'Monthwise 2019-20'!N15 -> 15038.096 | X14: =+'Monthwise 2020-21'!N15 -> 13181.323 | Y14: 14848.854 | Z14: 13810.143 | AA14: 14304.738 | AB14: 15398.268 | AC14: 15932.199 | AD14: 3916.343
A15: IOCL-HALDIA, WEST BENGAL | B15: 4714 | C15: 4105 | D15: 3873 | E15: 4023.659 | F15: 4513.268 | G15: 4518 | H15: 5417.613 | I15: 5502.045 | J15: 5836 | K15: 5714.545 | L15: 6042.124 | M15: 5685.672 | N15: 6877.963 | O15: 8071.753 | P15: 7490.247 | Q15: 7952.102 | R15: 7650.241 | S15: 7776.471 | T15: 7689.297 | U15: 7655.491 | V15: 7964.856 | W15: =+'Monthwise 2019-20'!N13 -> 6463.292 | X15: =+'Monthwise 2020-21'!N13 -> 6758.511 | Y15: 7305.459 | Z15: 8506.484 | AA15: 8059.59 | AB15: 6934.496 | AC15: 8507.224 | AD15: 2209.647
A16: IOCL-BARAUNI,BIHAR | B16: 2204 | C16: 3411 | D16: 3122 | E16: 2875.804 | F16: 2993.0572 | G16: 4304 | H16: 5082.222 | I16: 5553.486 | J16: 5469 | K16: 5634.293 | L16: 5940.302 | M16: 6184.182 | N16: 6207.428 | O16: 5730.016 | P16: 6344.727 | Q16: 6478.014 | R16: 5943.924 | S16: 6544.753 | T16: 6526.045 | U16: 5818.634 | V16: 6661.188 | W16: =+'Monthwise 2019-20'!N11 -> 6515.533 | X16: =+'Monthwise 2020-21'!N11 -> 5469.219 | Y16: 5619.663 | Z16: 6785.388 | AA16: 6617.698 | AB16: 6513.258 | AC16: 6380.177 | AD16: 1550.627
A17: IOCL-DIGBOI,ASSAM | B17: 554 | C17: 603 | D17: 679 | E17: 652.668 | F17: 580.841 | G17: 602 | H17: 651.096 | I17: 614.88 | J17: 586 | K17: 563.505 | L17: 623.105 | M17: 600.46 | N17: 651.006 | O17: 622.12 | P17: 660.315 | Q17: 651.232 | R17: 591.288 | S17: 561.833 | T17: 533.447 | U17: 665.623 | V17: 675.524 | W17: =+'Monthwise 2019-20'!N17 -> 664.233 | X17: =+'Monthwise 2020-21'!N17 -> 605.11 | Y17: 707.829 | Z17: 712.919 | AA17: 710.21 | AB17: 774.113 | AC17: 712.648 | AD17: 184.93
A18: IOCL-GUWAHATI,ASSAM | B18: 836 | C18: 914 | D18: 708 | E18: 655.9 | F18: 458.42 | G18: 890 | H18: 1004.022 | I18: 863.911 | J18: 839 | K18: 919.968 | L18: 1075.687 | M18: 1077.605 | N18: 1117.68 | O18: 1058.461 | P18: 956.452 | Q18: 1019.034 | R18: 1005.794 | S18: 903.523 | T18: 863.58101 | U18: 1023.684 | V18: 863.169 | W18: =+'Monthwise 2019-20'!N16 -> 892.403 | X18: =+'Monthwise 2020-21'!N16 -> 849.238 | Y18: 730.215 | Z18: 1079.669 | AA18: 1000.487 | AB18: 1178.2 | AC18: 1291.411 | AD18: 331.227
A19: IOCL-BONGAIGAON,ASSAM | B19: - | C19: - | D19: - | E19: - | F19: - | G19: - | H19: - | I19: - | J19: - | K19: - | L19: 2163.188 | M19: 2220.316 | N19: 2008.298 | O19: 2187.786 | P19: 2356.135 | Q19: 2327.514 | R19: 2402.949 | S19: 2441.664 | T19: 2485.791 | U19: 2401.586 | V19: 2512.773 | W19: =+'Monthwise 2019-20'!N18 -> 2044.824 | X19: =+'Monthwise 2020-21'!N18 -> 2450.461 | Y19: 2638.5 | Z19: 2775.043 | AA19: 3008.864 | AB19: 2772.082 | AC19: 3029.371 | AD19: 779.972
A20: IOCL -PARADIP | B20: - | C20: - | D20: - | E20: - | F20: - | G20: - | H20: - | I20: - | J20: - | K20: - | L20: - | M20: - | N20: - | O20: - | P20: - | Q20: - | R20: - | S20: 1816.6732 | T20: 8229.931 | U20: 12730.437 | V20: 14616.385 | W20: =+'Monthwise 2019-20'!N19 -> 15778.198 | X20: =+'Monthwise 2020-21'!N19 -> 12507.939 | Y20: 13217.398 | Z20: 13598.533 | AA20: 15213.432 | AB20: 14657.086 | AC20: 16345.755 | AD20: 3675.323
A21: IOCL TOTAL | B21: 30360 | C21: 32420 | D21: 33225 | E21: 33756.946 | F21: 35285.275 | G21: 37659 | H21: 36626.574 | I21: 38518.878 | J21: 44001 | K21: 47400.717 | L21: 51367.291 | M21: 50695.647 | N21: 52963.878 | O21: 55621.271 | P21: 54649.741 | Q21: 53126.361 | R21: 53586.067 | S21: 58007.48 | T21: 65190.518 | U21: 69001.177 | V21: 71815.866 | W21: =SUM(W12:W20) -> 69419.362 | X21: =SUM(X12:X20) -> 62350.647 | Y21: =SUM(Y12:Y20) -> 67664.868 | Z21: =SUM(Z12:Z20) -> 72408.09 | AA21: =SUM(AA12:AA20) -> 73307.735 | AB21: =SUM(AB12:AB20) -> 71564.369 | AC21: =SUM(AC12:AC20) -> 75450.428 | AD21: =SUM(AD12:AD20) -> 19164.617
A23: Hindustan Petroleum Corporation Ltd.(HPCL)
A24: HPCL-MUMBAI,MAHARASHTRA | B24: 5205 | C24: 6003 | D24: 5575 | E24: 5631.5 | F24: 6078.8 | G24: 6108 | H24: 6118 | I24: 6248.671 | J24: 7420 | K24: 7352.849 | L24: 6651.627 | M24: 6965.109 | N24: 6554.4251 | O24: 7506.4748 | P24: 7748.0328 | Q24: 7737.075 | R24: 7412.0069 | S24: 8015.1452 | T24: 8510.3189 | U24: 8641.1704 | V24: 8670.9297 | W24: =+'Monthwise 2019-20'!N40 -> 8065.1615 | X24: =+'Monthwise 2020-21'!N40 -> 7374.2081 | Y24: 5557.852 | Z24: 9804.3221 | AA24: 9639.7967 | AB24: 9957.7973 | AC24: 10006.692 | AD24: 2549.8876
A25: HPCL-VISAKH,ANDHRA PRADESH | B25: 3862 | C25: 4555 | D25: 6406 | E25: 6706.5 | F25: 6851.73 | G25: 7592 | H25: 7822.2 | I25: 7569.125 | J25: 9232 | K25: 9410.762 | L25: 9157.507 | M25: 8830.134 | N25: 8164.9 | O25: 8699.4567 | P25: 8011.1853 | Q25: 7775.91 | R25: 8766.638 | S25: 9220.4433 | T25: 9303.8726 | U25: 9635.0106 | V25: 9773.1385 | W25: =+'Monthwise 2019-20'!N41 -> 9115.0492 | X25: =+'Monthwise 2020-21'!N41 -> 9050.4725 | Y25: 8409.8301 | Z25: 9286.6363 | AA25: 12688.754 | AB25: 15309.832 | AC25: 16036.5 | AD25: 3973.6167
A26: HPCL-TOTAL | B26: =+B24+B25 -> 9067 | C26: =+C24+C25 -> 10558 | D26: =+D24+D25 -> 11981 | E26: =+E24+E25 -> 12338 | F26: =+F24+F25 -> 12930.53 | G26: =+G24+G25 -> 13700 | H26: =+H24+H25 -> 13940.2 | I26: =+I24+I25 -> 13817.796 | ... AD26: =+AD24+AD25 -> 6523.5044
A28: Bharat Petroleum Corporation Ltd (BPCL)
A29: BPCL-MUMBAI, MAHARASHTRA | B29: 8873 | C29: 8903 | D29: 8662 | E29: 8736.8 | F29: 8740.305 | G29: 8703 | H29: 9142.928 | I29: 10281.83 | J29: 12041 | K29: 12742.851 | L29: 12220.945 | M29: 12501.173 | N29: 12687.801 | O29: 12983.799 | P29: 12735.798 | Q29: 12683.87 | R29: 12820.792 | S29: 13371.259 | T29: 13541.11 | U29: 14054.056 | V29: 14772.714 | W29: =+'Monthwise 2019-20'!N28 -> 15016.676 | X29: =+'Monthwise 2020-21'!N28 -> 12940.595 | Y29: 14436.538 | Z29: 14546.072 | AA29: 15051.664 | AB29: 15529.085 | AC29: 16042.344 | AD29: 3821.4716
A30: BPCL-KOCHI,KERALA | B30: - | C30: - | D30: - | E30: - | J30: 7743 | K30: 8173.89 | L30: 7737.983 | M30: 7874.72 | N30: 8697.97 | O30: 9472.4303 | P30: 10105.449 | Q30: 10285.355 | R30: 10355.729 | S30: 10711.548 | T30: 11820.208 | U30: 14094.598 | V30: 16050.719 | W30: =+'Monthwise 2019-20'!N29 -> 16515.431 | X30: =+'Monthwise 2020-21'!N29 -> 13281.794 | Y30: 15401.509 | Z30: 16016.756 | AA30: 17314.243 | AB30: 17193.122 | AC30: 17559.45 | AD30: 4329.0026
A31: BPCL-BINA, SAGAR, MADHYA PRADESH | Z31: 7840.6879 | AA31: 7132.7313 | AB31: 7708.8551 | AC31: 7391.0413 | AD31: 2055.1705
A32: BPCL-TOTAL | B32: 8873 | C32: 8903 | D32: 8662 | E32: 8736.8 | F32: 8740.305 | G32: 8703 | H32: 9142.928 | I32: 10281.83 | J32: 19784 | K32: 20916.741 | L32: 19958.928 | M32: 20375.893 | N32: 21385.771 | O32: 24503.86 | P32: 28573.192 | Q32: 28419.137 | R32: 29385.092 | S32: 30485.012 | T32: 31721.3 | U32: 34856.558 | V32: 36539.315 | W32: =SUM(W29:W31) -> 31532.107 | X32: =SUM(X29:X31) -> 26222.389 | Y32: =SUM(Y29:Y31) -> 29838.047 | Z32: =SUM(Z29:Z31) -> 38403.516 | AA32: =SUM(AA29:AA31) -> 39498.638 | AB32: =SUM(AB29:AB31) -> 40431.062 | AC32: =SUM(AC29:AC31) -> 40992.836 | AD32: =SUM(AD29:AD31) -> 10205.645
A34: Numaligarh Refinery Ltd.(NRL) Numaligarh, Assam | B34: 0 | C34: 205 | D34: 1451 | E34: 2307.1 | F34: 1878.6 | G34: 2200 | H34: 2041.764 | I34: 2132.364 | J34: 2496 | K34: 2568.478 | L34: 2251.446 | M34: 2619.08 | N34: 2250.4041 | O34: 2824.989 | P34: 2478.0209 | Q34: 2612.936 | R34: 2776.6805 | S34: 2520.2685 | T34: 2683.1265 | U34: 2809.4262 | V34: 2900.3856 | W34: =+'Monthwise 2019-20'!N31 -> 2383.3388 | X34: =+'Monthwise 2020-21'!N31 -> 2707.3534 | Y34: 2624.4092 | Z34: 3091.3643 | AA34: 2509.6751 | AB34: 3065.5908 | AC34: 3112.5687 | AD34: 790.55533
A36: Chennai Petroleum Corporation Ltd (CPCL)
A37: CPCL-MANALI, TAMILNADU | B37: 6101 | C37: 6376 | D37: 6046 | E37: 6122.4 | F37: 6175.6 | G37: 6091 | H37: 8181 | I37: 9680.12 | J37: 9784 | K37: 9801.618 | L37: 9706.791 | M37: 9571.164 | N37: 10353.725 | O37: 9945.4056 | P37: 9098.1945 | Q37: 10068.038 | R37: 10247.281 | S37: 9099.1507 | T37: 9761.3696 | U37: 10288.832 | V37: 10271.333 | W37: =+'Monthwise 2019-20'!N23 -> 10160.637 | X37: =+'Monthwise 2020-21'!N23 -> 8242.8905 | Y37: 9040.4193 | Z37: 11315.722 | AA37: 11642.126 | AB37: 10453.71 | AC37: 11709.718 | AD37: 2847.758
A38: CPCL-NARIMANAM,TAMILNADU | B38: 644 | C38: 636 | D38: 579 | E38: 566 | F38: 643.2 | G38: 653 | H38: 743 | I38: 681.738 | J38: 617 | K38: 460.986 | L38: 418.144 | M38: 516.645 | N38: 705.817 | O38: 611.406 | P38: 639.685 | Q38: 558.952 | R38: 531.269 | S38: 543.559 | T38: 530.788 | U38: 500.177 | V38: 423.367 | W38: =+'Monthwise 2019-20'!N24 -> 0 | X38: 0 | Y38: 0 | Z38: 0 | AA38: 0 | AB38: 0 | AC38: 0 | AD38: 0
A39: CPCL-TOTAL | B39: 6745 | C39: 7012 | D39: 6625 | E39: 6688.4 | F39: 6818.8 | G39: 6744 | H39: 8924 | I39: 10361.858 | J39: 10401 | K39: 10262.604 | L39: 10124.935 | M39: 10087.809 | N39: 11059.542 | O39: 10556.812 | P39: 9737.8795 | Q39: 10626.989 | R39: 10778.55 | S39: 9642.7097 | T39: 10292.158 | U39: 10789.009 | V39: 10694.7 | W39: =SUM(W37:W38) -> 10160.637 | X39: =SUM(X37:X38) -> 8242.8905 | Y39: =SUM(Y37:Y38) -> 9040.4193 | Z39: =SUM(Z37:Z38) -> 11315.722 | AA39: =SUM(AA37:AA38) -> 11642.126 | AB39: =SUM(AB37:AB38) -> 10453.71 | AC39: =SUM(AC37:AC38) -> 11709.718 | AD39: =SUM(AD37:AD38) -> 2847.758
A41: Kochi Refinery Ltd.-KOCHI, KERALA | B41: 7770 | C41: 7830 | D41: 7520 | E41: 6796.8 | F41: 7579.6 | G41: 7854 | H41: 7924.523 | I41: 6939.062
A43: Bharat Oman Refineries Ltd.-Bina, Sagar M.P. | O43: 2047.6309 | P43: 5731.9456 | Q43: 5449.912 | R43: 6208.5709 | S43: 6402.205 | T43: 6359.9819 | U43: 6707.9037 | V43: 5715.8814 | W43: 7912.9059 | X43: 6189.63 | Y43: 7409.7564
A45: Bongaigaon Refinery & Petrochemicals Ltd. (BRPL)-Bongaigaon, Assam | B45: 1655 | C45: 1906 | D45: 1490 | E45: 1475.1 | F45: 1463.2 | G45: 2127 | H45: 2311.1 | I45: 2356.084 | J45: 2067 | K45: 2012.288
A47: HMEL-GGSR, BATHINDA, PUNJAB | P47: 4904.1724 | Q47: 9271.501 | R47: 7343.6321 | S47: 10713.305 | T47: 10521.457 | U47: 8830.195 | V47: 12472.804 | W47: 12242.064 | X47: 10072.002 | Y47: 13026.753 | Z47: 12735.301 | AA47: 12647.938 | AB47: 13044.807 | AC47: 11654.181 | AD47: 3314.554
A49: HRRL Pachpadra,Rajasthan | AD49: 142.07812
A51: Oil & Natural Gas Corporation Ltd.(ONGC)
A52: ONGC-TATIPAKA,ANDHRA PRADESH | B52: - | C52: - | D52: - | E52: 13.357 | F52: 84.964 | G52: 83 | H52: 92.579 | I52: 93.277 | J52: 94 | K52: 62.968 | L52: 83.329 | M52: 55.34 | N52: 68.478 | O52: 69.285 | P52: 56.519 | Q52: 65.226 | R52: 50.6517 | S52: 67.371527 | T52: 85.354346 | U52: 79.581655 | V52: 66.156254 | W52: =+'Monthwise 2019-20'!N35 -> 86.928253 | X52: =+'Monthwise 2020-21'!N35 -> 80.989877 | Y52: 75.132764 | Z52: 73.221178 | AA52: 65.409208 | AB52: 73.759835 | AC52: 74.318624 | AD52: 14.694203
A53: MRPL-MANGALORE,KARNATAKA | B53: 4069 | C53: 5202 | D53: 6438 | E53: 5487.5 | F53: 7253 | G53: 10068 | H53: 11809.092 | I53: 12014.157 | J53: 12536 | K53: 12524.739 | L53: 12576.132 | M53: 12497.793 | N53: 12662.32 | O53: 12798.359 | P53: 14414.827 | Q53: 14588.523 | R53: 14632.033 | S53: 15531.991 | T53: 15965.295 | U53: 16129.765 | V53: 16231.045 | W53: =+'Monthwise 2019-20'!N36 -> 13953.106 | X53: =+'Monthwise 2020-21'!N36 -> 11474.547 | Y53: 14870.675 | Z53: 17116.275 | AA53: 16533.436 | AB53: 18043.58 | AC53: 16773.906 | AD53: 4305.0293
A54: ONGC TOTAL | B54: 4069 | C54: 5202 | D54: 6438 | E54: 5500.857 | F54: 7337.964 | G54: 10151 | H54: 11901.671 | I54: 12107.434 | J54: 12630 | K54: 12587.707 | L54: 12659.461 | M54: 12553.133 | N54: 12730.798 | O54: 12867.644 | P54: 14471.346 | Q54: 14653.749 | R54: 14682.685 | S54: 15599.363 | T54: 16050.649 | U54: 16209.347 | V54: 16297.201 | W54: =SUM(W52:W53) -> 14040.034 | X54: =SUM(X52:X53) -> 11555.537 | Y54: =SUM(Y52:Y53) -> 14945.807 | Z54: =SUM(Z52:Z53) -> 17189.497 | AA54: =SUM(AA52:AA53) -> 16598.845 | AB54: =SUM(AB52:AB53) -> 18117.34 | AC54: =SUM(AC52:AC53) -> 16848.224 | AD54: =SUM(AD52:AD53) -> 4319.7235
A55: Reliance Industries Ltd. (RIL)
A56: RIL,JAMNAGAR,GUJARAT | B56: - | C56: 11673 | D56: 25716 | E56: 28940.77 | F56: 28546.76 | G56: 29542 | H56: 31489.515 | I56: 30470.858 | J56: 31670 | K56: 31795.486 | L56: 31971.171 | M56: 31378.672 | N56: 31047.574 | O56: 32494.499 | P56: 32613.44 | Q56: 30304.822 | R56: 30867.395 | S56: 32428.384 | T56: 32823.151 | U56: 33152.75 | V56: 31752.151 | W56: =+'Monthwise 2019-20'!N46 -> 33018.532 | X56: =+'Monthwise 2020-21'!N46 -> 34099.68 | Y56: 34757.067 | Z56: 34433.469 | AA56: 34390.101 | AB56: 34990.493 | AC56: 33646.362 | AD56: 6824.6124
...

Sheet Monthwise 2024-25 (P)
C2: Petroleum Planning & Analysis Cell
A7: 2024-25 (P) | I7: ('000 Metric Tonnes)
A8: Crude Oil Processed by Refineries
A9: OIL COMPANIES | B9: APR | C9: MAY | D9: JUN | E9: JULY | F9: AUG | G9: SEP | H9: OCT | I9: NOV | J9: DEC | K9: JAN | L9: FEB | M9: MAR | N9: TOTAL
A10: Indian Oil Corporation Ltd.(IOCL)
A11: IOCL-BARAUNI,BIHAR | B11: 545.016 | C11: 548.748 | D11: 566.248 | E11: 585.922 | F11: 586.958 | G11: 485.732 | H11: 576.141 | I11: 569.051 | J11: 599.191 | K11: 543.603 | L11: 455.991 | M11: 450.657 | N11: =SUM(B11:M11) -> 6513.258
A12: IOCL-KOYALI, GUJARAT | B12: 1290.767 | C12: 1326.322 | D12: 1300.029 | E12: 1351.865 | F12: 1342.543 | G12: 1315.614 | H12: 1356.925 | I12: 1318.246 | J12: 1317.773 | K12: 1315.571 | L12: 930.32 | M12: 1117.071 | N12: =SUM(B12:M12) -> 15283.046
A13: IOCL-HALDIA, WEST BENGAL | B13: 656.298 | C13: 689.531 | D13: 672.644 | E13: 666.788 | F13: 283.855 | G13: 38.054 | H13: 364.325 | I13: 702.642 | J13: 747.231 | K13: 744.383 | L13: 641.585 | M13: 727.16 | N13: =SUM(B13:M13) -> 6934.496
A14: IOCL-MATHURA, UTTAR PRADESH | B14: 859.672 | C14: 839.721 | D14: 845.114 | E14: 688.444 | F14: 589.305 | G14: 585.737 | H14: 41.683 | I14: 323.194 | J14: 874.386 | K14: 740.418 | L14: 790.154 | M14: 875.992 | N14: =SUM(B14:M14) -> 8053.82
A15: IOCL-PANIPAT, HARYANA | B15: 1283.054 | C15: 1269.28 | D15: 1298.853 | E15: 1241.434 | F15: 1151.372 | G15: 1248.088 | H15: 1353.397 | I15: 1354.485 | J15: 1389.798 | K15: 1318.665 | L15: 1163.738 | M15: 1326.104 | N15: =SUM(B15:M15) -> 15398.268
A16: IOCL-GUWAHATI,ASSAM | B16: 108.917 | C16: 110.964 | D16: 107.508 | E16: 104.554 | F16: 101.195 | G16: 86.565 | H16: 109.884 | I16: 91.723 | J16: 41.827 | K16: 105.425 | L16: 98.789 | M16: 110.849 | N16: =SUM(B16:M16) -> 1178.2
A17: IOCL-DIGBOI,ASSAM | B17: 64.893 | C17: 65.042 | D17: 63.447 | E17: 57.407 | F17: 68.373 | G17: 59.009 | H17: 71.024 | I17: 69.129 | J17: 63.095 | K17: 66.347 | L17: 60.173 | M17: 66.174 | N17: =SUM(B17:M17) -> 774.113
A18: IOCL-BONGAIGAON,ASSAM | B18: 244.486 | C18: 60.204 | D18: 217.61 | E18: 252.608 | F18: 236.846 | G18: 243.462 | H18: 253.93 | I18: 251.536 | J18: 260.036 | K18: 257.121 | L18: 235.646 | M18: 258.597 | N18: =SUM(B18:M18) -> 2772.082
A19: IOCL-PARADIP,ODISHA | B19: 1093.706 | C19: 1155.403 | D19: 884.313 | E19: 907.582 | F19: 1230.418 | G19: 1228.018 | H19: 1272.95 | I19: 1333.392 | J19: 1403.143 | K19: 1436.19 | L19: 1296.51 | M19: 1415.461 | N19: =SUM(B19:M19) -> 14657.086
A20: IOCL TOTAL | B20: =SUM(B11:B19) -> 6146.809 | C20: =SUM(C11:C19) -> 6065.215 | D20: =SUM(D11:D19) -> 5955.766 | E20: =SUM(E11:E19) -> 5856.604 | F20: =SUM(F11:F19) -> 5590.865 | G20: =SUM(G11:G19) -> 5290.279 | H20: =SUM(H11:H19) -> 5400.259 | I20: =SUM(I11:I19) -> 6013.398 | ... N20: =SUM(N11:N19) -> 71564.369
A22: Chennai Petroleum Corporation Ltd. (CPCL)
A23: CPCL-MANALI, TAMILNADU | B23: 867.12083 | C23: 1032.677 | D23: 930.19467 | E23: 879.99293 | F23: 680.62608 | G23: 537.82806 | H23: 704.52458 | I23: 901.68117 | J23: 945.45558 | K23: 1002.4172 | L23: 950.91376 | M23: 1020.2786 | N23: =SUM(B23:M23) -> 10453.71
A24: CPCL-NARIMANAM,TAMILNADU | B24: 0 | C24: 0 | D24: 0 | E24: 0 | F24: 0 | G24: 0 | H24: 0 | I24: 0 | J24: 0 | K24: 0 | L24: 0 | M24: 0 | N24: =SUM(B24:M24) -> 0
A25: CPCL-TOTAL | B25: =SUM(B23:B24) -> 867.12083 | C25: =SUM(C23:C24) -> 1032.677 | D25: =SUM(D23:D24) -> 930.19467 | E25: =SUM(E23:E24) -> 879.99293 | F25: =SUM(F23:F24) -> 680.62608 | G25: =SUM(G23:G24) -> 537.82806 | H25: =SUM(H23:H24) -> 704.52458 | I25: =SUM(I23:I24) -> 901.68117 | ... M25: =SUM(M23:M24) -> 1020.2786 | N25: =SUM(B25:M25) -> 10453.71
A27: Bharat Petroleum Corporation Ltd. (BPCL)
A28: BPCL-MUMBAI, MAHARASHTRA | B28: 1357.7674 | C28: 1284.2996 | D28: 1120.8574 | E28: 1364.2861 | F28: 1360.3837 | G28: 1354.5215 | H28: 1418.942 | I28: 954.9911 | J28: 1243.6455 | K28: 1390.5467 | L28: 1279.2568 | M28: 1399.587 | N28: =SUM(B28:M28) -> 15529.085
A29: BPCL-KOCHI, KERALA | B29: 1424.937 | C29: 1507.95 | D29: 1482.257 | E29: 1549.85 | F29: 1506.6311 | G29: 1307.638 | H29: 989.324 | I29: 1355.6841 | J29: 1567.14 | K29: 1522.876 | L29: 1421.84 | M29: 1556.995 | N29: =SUM(B29:M29) -> 17193.122
A30: BPCL-BINA, MADHYA PRADESH | B30: 660.12702 | C30: 661.4631 | D30: 678.21012 | E30: 685.05809 | F30: 531.94384 | G30: 489.35251 | H30: 685.98645 | I30: 661.83065 | J30: 686.51385 | K30: 687.71159 | L30: 616.16779 | M30: 664.49008 | N30: =SUM(B30:M30) -> 7708.8551
A31: BPCL-TOTAL | B31: =SUM(B28:B30) -> 3442.8314 | C31: =SUM(C28:C30) -> 3453.7127 | D31: =SUM(D28:D30) -> 3281.3245 | E31: =SUM(E28:E30) -> 3599.1941 | F31: =SUM(F28:F30) -> 3398.9587 | G31: =SUM(G28:G30) -> 3151.512 | H31: =SUM(H28:H30) -> 3094.2525 | I31: =SUM(I28:I30) -> 2972.5058 | ... M31: =SUM(M28:M30) -> 3621.0721 | N31: =SUM(B31:M31) -> 40431.062
A32: NRL-NUMALIGARH, ASSAM | B32: 241.34369 | C32: 276.873 | D32: 245.90061 | E32: 217.67252 | F32: 216.2379 | G32: 249.50487 | H32: 272.03403 | I32: 261.05313 | J32: 275.39615 | K32: 287.5963 | L32: 248.82234 | M32: 273.15627 | N32: =SUM(B32:M32) -> 3065.5908
A34: Oil & Natural Gas Corporation Ltd. (ONGC)
A35: ONGC-TATIPAKA,ANDHRA PRADESH | B35: 4.9729755 | C35: 6.0295064 | D35: 5.9835026 | E35: 5.9835026 | F35: 6.1447555 | G35: 5.83 | H35: 6.1193467 | I35: 7.4162456 | J35: 7.695 | K35: 7.014 | L35: 5.232 | M35: 5.339 | N35: =SUM(B35:M35) -> 73.759835
A36: MRPL-MANGALORE,KARNATAKA | B36: 1312.1558 | C36: 1593.2484 | D36: 1474.3448 | E36: 1478.1382 | F36: 1496.5125 | G36: 1464.1682 | H36: 1486.1066 | I36: 1506.8482 | J36: 1548.4366 | K36: 1576.5602 | L36: 1461.2086 | M36: 1645.852 | N36: =SUM(B36:M36) -> 18043.58
A37: ONGC TOTAL | B37: =SUM(B35:B36) -> 1317.1288 | C37: =SUM(C35:C36) -> 1599.2779 | D37: =SUM(D35:D36) -> 1480.3283 | E37: =SUM(E35:E36) -> 1484.1217 | F37: =SUM(F35:F36) -> 1502.6573 | G37: =SUM(G35:G36) -> 1469.9982 | H37: =SUM(H35:H36) -> 1492.2259 | I37: =SUM(I35:I36) -> 1514.2645 | ... M37: =SUM(M35:M36) -> 1651.191 | N37: =SUM(B37:M37) -> 18117.34
A39: Hindustan Petroleum Corporation Ltd. (HPCL)
A40: HPCL-MUMBAI,MAHARASHTRA | B40: 519.56529 | C40: 816.25993 | D40: 884.82617 | E40: 865.32819 | F40: 741.85354 | G40: 868.49655 | H40: 878.54452 | I40: 878.42318 | J40: 901.78185 | K40: 883.28362 | L40: 806.06407 | M40: 913.37034 | N40: =SUM(B40:M40) -> 9957.7973
A41: HPCL-VISAKH,ANDHRA PRADESH | B41: 900.04068 | C41: 1354.3162 | D41: 1290.2101 | E41: 1309.6035 | F41: 1252.0051 | G41: 1263.1293 | H41: 1184.6579 | I41: 1269.1054 | J41: 1357.3178 | K41: 1422.9517 | L41: 1308.3301 | M41: 1398.1638 | N41: =SUM(B41:M41) -> 15309.832
A42: HMEL-GGSR, BATHINDA, PUNJAB | B42: 1082.552 | C42: 1110.92 | D42: 1076.522 | E42: 1111.368 | F42: 1098.976 | G42: 1060.853 | H42: 1101.851 | I42: 1070.781 | J42: 1109.522 | K42: 1115.935 | L42: 999.695 | M42: 1105.8317 | N42: =SUM(B42:M42) -> 13044.807 | P42: 13044.807
A43: HPCL-TOTAL | B43: =SUM(B40:B42) -> 2502.158 | C43: =SUM(C40:C42) -> 3281.4961 | D43: =SUM(D40:D42) -> 3251.5583 | E43: =SUM(E40:E42) -> 3286.2997 | F43: =SUM(F40:F42) -> 3092.8347 | G43: =SUM(G40:G42) -> 3192.4789 | H43: =SUM(H40:H42) -> 3165.0534 | I43: =SUM(I40:I42) -> 3218.3096 | ... M43: =SUM(M40:M42) -> 3417.3658 | N43: =SUM(B43:M43) -> 38312.436
A45: Reliance Industries Ltd. (RIL)
A46: RIL,JAMNAGAR,GUJARAT | B46: 2884.8105 | C46: 2932.6956 | D46: 2832.0782 | E46: 2985.8246 | F46: 2921.4631 | G46: 2936.4629 | H46: 2842.8005 | I46: 2846.4255 | J46: 3058.7522 | K46: 3031.6822 | L46: 2763.1451 | M46: 2954.3521 | N46: =SUM(B46:M46) -> 34990.493
A47: RIL-(SEZ), JAMNAGAR,GUJARAT | B47: 2516.4372 | C47: 2657.3979 | D47: 2627.2446 | E47: 2512.4711 | F47: 2478.9284 | G47: 2697.4291 | H47: 2586.7316 | I47: 2390.5333 | J47: 2723.8281 | K47: 2577.8787 | L47: 2555.6919 | M47: 2867 | N47: =SUM(B47:M47) -> 31191.572 | P47: =+N47/1000 -> 31.191572
A48: RIL TOTAL | B48: =SUM(B46:B47) -> 5401.2477 | C48: =SUM(C46:C47) -> 5590.0936 | D48: =SUM(D46:D47) -> 5459.3228 | E48: =SUM(E46:E47) -> 5498.2957 | F48: =SUM(F46:F47) -> 5400.3915 | G48: =SUM(G46:G47) -> 5633.8921 | H48: =SUM(H46:H47) -> 5429.532 | I48: =SUM(I46:I47) -> 5236.9588 | ... M48: =SUM(M46:M47) -> 5821.3521 | N48: =SUM(B48:M48) -> 66182.064
A50: NEL-VADINAR,GUJARAT | B50: 1698.6148 | C50: 1727.4771 | D50: 1598.3206 | E50: 1763.8461 | F50: 1752.8784 | G50: 1677.1037 | H50: 1745.6488 | I50: 1695.002 | J50: 1748.1649 | K50: 1744.4977 | L50: 1584.1349 | M50: 1751.0654 | N50: =SUM(B50:M50) -> 20486.754
A52: GRAND TOTAL | B52: =+B50+B48+B43+B37+B32+B31+B25+B20 -> 21617.254 | C52: =+C50+C48+C43+C37+C32+C31+C25+C20 -> 23026.822 | D52: =+D50+D48+D43+D37+D32+D31+D25+D20 -> 22202.716 | E52: =+E50+E48+E43+E37+E32+E31+E25+E20 -> 22586.027 | F52: =+F50+F48+F43+F37+F32+F31+F25+F20 -> 21635.45 | G52: =+G50+G48+G43+G37+G32+G31+G25+G20 -> 21202.597 | H52: =+H50+H48+H43+H37+H32+H31+H25+H20 -> 21303.53 | I52: =+I50+I48+I43+I37+I32+I31+I25+I20 -> 21813.173 | ... M52: =+M50+M48+M43+M37+M32+M31+M25+M20 -> 23903.546 | N52: =SUM(B52:M52) -> 268613.33 | P52: 268613.33
...

Sheet Monthwise 2023-24 (P)
C2: Petroleum Planning & Analysis Cell
A7: 2023-24 (P) | I7: ('000 Metric Tonnes)
A8: Crude Oil Processed by Refineries
A9: OIL COMPANIES | B9: APR | C9: MAY | D9: JUN | E9: JULY | F9: AUG | G9: SEP | H9: OCT | I9: NOV | J9: DEC | K9: JAN | L9: FEB | M9: MAR | N9: TOTAL
A10: Indian Oil Corporation Ltd.(IOCL)
A11: IOCL-BARAUNI,BIHAR | B11: 546.511 | C11: 579.563 | D11: 491.922 | E11: 559.564 | F11: 590.767 | G11: 529.029 | H11: 503.428 | I11: 553.582 | J11: 597.971 | K11: 517.572 | L11: 541.973 | M11: 605.816 | N11: =SUM(B11:M11) -> 6617.698
A12: IOCL-KOYALI, GUJARAT | B12: 1121.574 | C12: 1330.391 | D12: 1275.124 | E12: 1330.927 | F12: 1262.851 | G12: 1169.638 | H12: 1279.385 | I12: 1290.125 | J12: 1330.241 | K12: 1191.573 | L12: 1249.939 | M12: 1370.42 | N12: =SUM(B12:M12) -> 15202.188
A13: IOCL-HALDIA, WEST BENGAL | B13: 706.283 | C13: 720.08 | D13: 691.684 | E13: 677.193 | F13: 689.547 | G13: 325.103 | H13: 674.352 | I13: 692.393 | J13: 726.875 | K13: 742.016 | L13: 678.344 | M13: 735.72 | N13: =SUM(B13:M13) -> 8059.59
A14: IOCL-MATHURA, UTTAR PRADESH | B14: 836.709 | C14: 833.518 | D14: 808.159 | E14: 436.214 | F14: 680.978 | G14: 721.789 | H14: 852.622 | I14: 864.519 | J14: 815.413 | K14: 646.127 | L14: 793.509 | M14: 900.971 | N14: =SUM(B14:M14) -> 9190.528
A15: IOCL-PANIPAT, HARYANA | B15: 1251.74 | C15: 1263.153 | D15: 1277.621 | E15: 1220.09 | F15: 1230.308 | G15: 1194.475 | H15: 1300.179 | I15: 1308.487 | J15: 1246.483 | K15: 1213.868 | L15: 693.247 | M15: 1105.087 | N15: =SUM(B15:M15) -> 14304.738
A16: IOCL-GUWAHATI,ASSAM | B16: 93.997 | C16: 96.304 | D16: 92.45 | E16: 94.729 | F16: 94.248 | G16: 90.035 | H16: 0.136 | I16: 33.126 | J16: 97.183 | K16: 95.741 | L16: 99.025 | M16: 113.513 | N16: =SUM(B16:M16) -> 1000.487
A17: IOCL-DIGBOI,ASSAM | B17: 43.905 | C17: 64.398 | D17: 62.73 | E17: 63.471 | F17: 19.81 | G17: 51.973 | H17: 66.2 | I17: 66.297 | J17: 69.082 | K17: 68.879 | L17: 64.694 | M17: 68.771 | N17: =SUM(B17:M17) -> 710.21
A18: IOCL-BONGAIGAON,ASSAM | B18: 249.599 | C18: 257.896 | D18: 251.252 | E18: 236.572 | F18: 254.941 | G18: 251.375 | H18: 257.969 | I18: 249.586 | J18: 255.87 | K18: 251.932 | L18: 238.897 | M18: 252.975 | N18: =SUM(B18:M18) -> 3008.864
A19: IOCL-PARADIP,ODISHA | B19: 1187.322 | C19: 1272.101 | D19: 1346.431 | E19: 1394.489 | F19: 1429.008 | G19: 1172.854 | H19: 722.076 | I19: 1260.942 | J19: 1387.383 | K19: 1363.85 | L19: 1271.302 | M19: 1405.674 | N19: =SUM(B19:M19) -> 15213.432
A20: IOCL TOTAL | B20: =SUM(B11:B19) -> 6037.64 | C20: =SUM(C11:C19) -> 6417.404 | D20: =SUM(D11:D19) -> 6297.373 | E20: =SUM(E11:E19) -> 6013.249 | F20: =SUM(F11:F19) -> 6252.458 | G20: =SUM(G11:G19) -> 5506.271 | H20: =SUM(H11:H19) -> 5656.347 | I20: =SUM(I11:I19) -> 6319.057 | ... N20: =SUM(N11:N19) -> 73307.735
A22: Chennai Petroleum Corporation Ltd. (CPCL)
A23: CPCL-MANALI, TAMILNADU | B23: 919.51965 | C23: 941.28227 | D23: 816.58033 | E23: 1040.1547 | F23: 1000.3788 | G23: 1007.9709 | H23: 1007.2306 | I23: 1001.0375 | J23: 820.50098 | K23: 1001.2367 | L23: 1013.9262 | M23: 1072.3076 | N23: =SUM(B23:M23) -> 11642.126
A24: CPCL-NARIMANAM,TAMILNADU | B24: 0 | C24: 0 | D24: 0 | E24: 0 | F24: 0 | G24: 0 | H24: 0 | I24: 0 | J24: 0 | K24: 0 | L24: 0 | M24: 0 | N24: =SUM(B24:M24) -> 0
A25: CPCL-TOTAL | B25: =SUM(B23:B24) -> 919.51965 | C25: =SUM(C23:C24) -> 941.28227 | D25: =SUM(D23:D24) -> 816.58033 | E25: =SUM(E23:E24) -> 1040.1547 | F25: =SUM(F23:F24) -> 1000.3788 | G25: =SUM(G23:G24) -> 1007.9709 | H25: =SUM(H23:H24) -> 1007.2306 | I25: =SUM(I23:I24) -> 1001.0375 | ... M25: =SUM(M23:M24) -> 1072.3076 | N25: =SUM(B25:M25) -> 11642.126
A27: Bharat Petroleum Corporation Ltd. (BPCL)
A28: BPCL-MUMBAI, MAHARASHTRA | B28: 1258.5681 | C28: 1332.1494 | D28: 1367.8604 | E28: 1367.9901 | F28: 1386.5438 | G28: 1354.5265 | H28: 740.45859 | I28: 927.63206 | J28: 1390.3368 | K28: 1156.903 | L28: 1307.1529 | M28: 1461.542 | N28: =SUM(B28:M28) -> 15051.664
A29: BPCL-KOCHI, KERALA | B29: 1384.5585 | C29: 1464.343 | D29: 1467.8116 | E29: 1389.2883 | F29: 1345.9017 | G29: 1299.3585 | H29: 1543.8253 | I29: 1506.9807 | J29: 1563.3872 | K29: 1588.215 | L29: 1203.8006 | M29: 1556.7726 | N29: =SUM(B29:M29) -> 17314.243
A30: BPCL-BINA, MADHYA PRADESH | B30: 593.53419 | C30: 660.47596 | D30: 579.83205 | E30: 48.042254 | F30: 485.23947 | G30: 680.19826 | H30: 710.06437 | I30: 682.46119 | J30: 666.15554 | K30: 731.35795 | L30: 663.63173 | M30: 631.73835 | N30: =SUM(B30:M30) -> 7132.7313
A31: BPCL-TOTAL | B31: =SUM(B28:B30) -> 3236.6607 | C31: =SUM(C28:C30) -> 3456.9684 | D31: =SUM(D28:D30) -> 3415.5041 | E31: =SUM(E28:E30) -> 2805.3206 | F31: =SUM(F28:F30) -> 3217.6849 | G31: =SUM(G28:G30) -> 3334.0833 | H31: =SUM(H28:H30) -> 2994.3482 | I31: =SUM(I28:I30) -> 3117.074 | ... M31: =SUM(M28:M30) -> 3650.053 | N31: =SUM(B31:M31) -> 39498.638
A32: NRL-NUMALIGARH, ASSAM | B32: -3.0121e-05 | C32: 61.302009 | D32: 8.2987979 | E32: 245.10472 | F32: 256.75533 | G32: 275.94873 | H32: 285.83246 | I32: 280.21689 | J32: 287.16653 | K32: 261.67366 | L32: 261.59649 | M32: 285.77949 | N32: =SUM(B32:M32) -> 2509.6751
A34: Oil & Natural Gas Corporation Ltd. (ONGC)
A35: ONGC-TATIPAKA,ANDHRA PRADESH | B35: 6.627859 | C35: 6.363207 | D35: 5.61208 | E35: 5.378 | F35: 5.032684 | G35: 4.184186 | H35: 4.80511 | I35: 4.603547 | J35: 5.703727 | K35: 6.009278 | L35: 5.642185 | M35: 5.447345 | N35: =SUM(B35:M35) -> 65.409208
A36: MRPL-MANGALORE,KARNATAKA | B36: 1468.9173 | C36: 1494.167 | D36: 1452.4719 | E36: 1438.501 | F36: 990.46701 | G36: 764.896 | H36: 1354.5848 | I36: 1499.2009 | J36: 1558.2502 | K36: 1527.4772 | L36: 1462.331 | M36: 1522.1715 | N36: =SUM(B36:M36) -> 16533.436
A37: ONGC TOTAL | B37: =SUM(B35:B36) -> 1475.5452 | C37: =SUM(C35:C36) -> 1500.5302 | D37: =SUM(D35:D36) -> 1458.084 | E37: =SUM(E35:E36) -> 1443.879 | F37: =SUM(F35:F36) -> 995.49969 | G37: =SUM(G35:G36) -> 769.08019 | H37: =SUM(H35:H36) -> 1359.3899 | I37: =SUM(I35:I36) -> 1503.8044 | ... M37: =SUM(M35:M36) -> 1527.6188 | N37: =SUM(B37:M37) -> 16598.845
A39: Hindustan Petroleum Corporation Ltd. (HPCL)
A40: HPCL-MUMBAI,MAHARASHTRA | B40: 837.11219 | C40: 790.7576 | D40: 809.84896 | E40: 892.92643 | F40: 785.24377 | G40: 846.74919 | H40: 898.0061 | I40: 858.19044 | J40: 842.76384 | K40: 853.94691 | L40: 679.64581 | M40: 544.60548 | N40: =SUM(B40:M40) -> 9639.7967
A41: HPCL-VISAKH,ANDHRA PRADESH | B41: 844.74487 | C41: 1066.1159 | D41: 1049.803 | E41: 1108.6857 | F41: 1104.989 | G41: 1013.1681 | H41: 1010.0615 | I41: 826.44583 | J41: 907.85425 | K41: 1180.3597 | L41: 1254.0021 | M41: 1322.5238 | N41: =SUM(B41:M41) -> 12688.754
A42: HMEL-GGSR, BATHINDA, PUNJAB | B42: 1073.099 | C42: 1101.057 | D42: 1062.368 | E42: 1102.121 | F42: 1106.148 | G42: 1074.65 | H42: 1104.277 | I42: 1074.422 | J42: 1109.948 | K42: 851.845 | L42: 884.578 | M42: 1103.425 | N42: =SUM(B42:M42) -> 12647.938
A43: HPCL-TOTAL | B43: =SUM(B40:B42) -> 2754.9561 | C43: =SUM(C40:C42) -> 2957.9305 | D43: =SUM(D40:D42) -> 2922.0199 | E43: =SUM(E40:E42) -> 3103.7331 | F43: =SUM(F40:F42) -> 2996.3808 | G43: =SUM(G40:G42) -> 2934.5673 | H43: =SUM(H40:H42) -> 3012.3446 | I43: =SUM(I40:I42) -> 2759.0583 | ... M43: =SUM(M40:M42) -> 2970.5543 | N43: =SUM(B43:M43) -> 34976.488
A45: Reliance Industries Ltd. (RIL)
A46: RIL,JAMNAGAR,GUJARAT | B46: 2841.6846 | C46: 2882.3533 | D46: 2783.2606 | E46: 2951.3848 | F46: 2939.4492 | G46: 2807.1476 | H46: 2925.2688 | I46: 2796.6843 | J46: 2784.6545 | K46: 2966.8087 | L46: 2695.0936 | M46: 3016.3114 | N46: =SUM(B46:M46) -> 34390.101
A47: RIL-(SEZ), JAMNAGAR,GUJARAT | B47: 2514.054 | C47: 2765.424 | D47: 2254.0599 | E47: 2564.6453 | F47: 2538.7188 | G47: 1986.6959 | H47: 1595.322 | I47: 2216.7866 | J47: 2493.785 | K47: 2615.9076 | L47: 2192.1304 | M47: 2562.4195 | N47: =SUM(B47:M47) -> 28299.949
A48: RIL TOTAL | B48: =SUM(B46:B47) -> 5355.7386 | C48: =SUM(C46:C47) -> 5647.7773 | D48: =SUM(D46:D47) -> 5037.3205 | E48: =SUM(E46:E47) -> 5516.0301 | F48: =SUM(F46:F47) -> 5478.168 | G48: =SUM(G46:G47) -> 4793.8435 | H48: =SUM(H46:H47) -> 4520.5908 | I48: =SUM(I46:I47) -> 5013.471 | ... M48: =SUM(M46:M47) -> 5578.7309 | N48: =SUM(B48:M48) -> 62690.05
A50: NEL-VADINAR,GUJARAT | B50: 1670.5646 | C50: 1743.3694 | D50: 1583.2639 | E50: 1717.6506 | F50: 1727.1074 | G50: 1666.7337 | H50: 1726.2895 | I50: 1674.5996 | J50: 1729.7247 | K50: 1732.7476 | L50: 1622.2892 | M50: 1728.1094 | N50: =SUM(B50:M50) -> 20322.45
A52: GRAND TOTAL | B52: =+B50+B48+B43+B37+B32+B31+B25+B20 -> 21450.625 | C52: =+C50+C48+C43+C37+C32+C31+C25+C20 -> 22726.564 | D52: =+D50+D48+D43+D37+D32+D31+D25+D20 -> 21538.445 | E52: =+E50+E48+E43+E37+E32+E31+E25+E20 -> 21885.122 | F52: =+F50+F48+F43+F37+F32+F31+F25+F20 -> 21924.433 | G52: =+G50+G48+G43+G37+G32+G31+G25+G20 -> 20288.499 | H52: =+H50+H48+H43+H37+H32+H31+H25+H20 -> 20562.373 | I52: =+I50+I48+I43+I37+I32+I31+I25+I20 -> 21668.319 | ... M52: =+M50+M48+M43+M37+M32+M31+M25+M20 -> 23372.1 | N52: =SUM(B52:M52) -> 261546.01
...

Sheet Monthwise 2022-23
C2: Petroleum Planning & Analysis Cell
A7: 2022-23 (P) | I7: ('000 Metric Tonnes)
A8: Crude Oil Processed by Refineries
A9: OIL COMPANIES | B9: APR | C9: MAY | D9: JUN | E9: JULY | F9: AUG | G9: SEP | H9: OCT | I9: NOV | J9: DEC | K9: JAN | L9: FEB | M9: MAR | N9: TOTAL
A10: Indian Oil Corporation Ltd.(IOCL)
A11: IOCL-BARAUNI,BIHAR | B11: 550.61 | C11: 584.471 | D11: 559.48 | E11: 558.619 | F11: 590.377 | G11: 544.498 | H11: 568.944 | I11: 573.349 | J11: 529.961 | K11: 602.134 | L11: 542.971 | M11: 579.974 | N11: =SUM(B11:M11) -> 6785.388
A12: IOCL-KOYALI, GUJARAT | B12: 1317.966 | C12: 1358.941 | D12: 1314.779 | E12: 1303.932 | F12: 1277.892 | G12: 1270.872 | H12: 1323.401 | I12: 1254.255 | J12: 1326.199 | K12: 1259.753 | L12: 1212.844 | M12: 1346.065 | N12: =SUM(B12:M12) -> 15566.899
A13: IOCL-HALDIA, WEST BENGAL | B13: 706.389 | C13: 712.4 | D13: 678.74 | E13: 722.079 | F13: 708.569 | G13: 701.738 | H13: 724.582 | I13: 708.099 | J13: 731.493 | K13: 704.666 | L13: 665.211 | M13: 742.518 | N13: =SUM(B13:M13) -> 8506.484
A14: IOCL-MATHURA, UTTAR PRADESH | B14: 805.128 | C14: 812.96 | D14: 867.721 | E14: 714.635 | F14: 649.596 | G14: 767.405 | H14: 794.588 | I14: 836.842 | J14: 879.89 | K14: 805.757 | L14: 740.612 | M14: 897.878 | N14: =SUM(B14:M14) -> 9573.012
A15: IOCL-PANIPAT, HARYANA | B15: 1172.269 | C15: 1252.496 | D15: 1253.85 | E15: 1154.627 | F15: 1207.093 | G15: 1153.66 | H15: 1184.838 | I15: 699.935 | J15: 890.409 | K15: 1334.66 | L15: 1208.346 | M15: 1297.96 | N15: =SUM(B15:M15) -> 13810.143
A16: IOCL-GUWAHATI,ASSAM | B16: 89.858 | C16: 93.836 | D16: 92.078 | E16: 93.183 | F16: 91.191 | G16: 86.646 | H16: 93.188 | I16: 89.338 | J16: 73.437 | K16: 94.014 | L16: 86.093 | M16: 96.807 | N16: =SUM(B16:M16) -> 1079.669
A17: IOCL-DIGBOI,ASSAM | B17: 58.027 | C17: 62.265 | D17: 60.928 | E17: 62.855 | F17: 61.161 | G17: 44.346 | H17: 62.418 | I17: 59.687 | J17: 61.964 | K17: 62.728 | L17: 57.145 | M17: 59.395 | N17: =SUM(B17:M17) -> 712.919
A18: IOCL-BONGAIGAON,ASSAM | B18: 209.041 | C18: 182.523 | D18: 185.649 | E18: 211.022 | F18: 248.882 | G18: 244.44 | H18: 254.147 | I18: 244.087 | J18: 251.224 | K18: 253.069 | L18: 233.224 | M18: 257.735 | N18: =SUM(B18:M18) -> 2775.043
A19: IOCL-PARADIP,ODISHA | B19: 1327.975 | C19: 1362.514 | D19: 1263.578 | E19: 1346.238 | F19: 2.099 | G19: 274.672 | H19: 1239.112 | I19: 1330.617 | J19: 1416.576 | K19: 1425.155 | L19: 1191.958 | M19: 1418.039 | N19: =SUM(B19:M19) -> 13598.533
A20: IOCL TOTAL | B20: =SUM(B11:B19) -> 6237.263 | C20: =SUM(C11:C19) -> 6422.406 | D20: =SUM(D11:D19) -> 6276.803 | E20: =SUM(E11:E19) -> 6167.19 | F20: =SUM(F11:F19) -> 4836.86 | G20: =SUM(G11:G19) -> 5088.277 | H20: =SUM(H11:H19) -> 6245.218 | I20: =SUM(I11:I19) -> 5796.209 | ... N20: =SUM(N11:N19) -> 72408.09
A22: Chennai Petroleum Corporation Ltd. (CPCL)
A23: CPCL-MANALI, TAMILNADU | B23: 904.19783 | C23: 1005.4421 | D23: 972.60578 | E23: 975.06522 | F23: 940.43378 | G23: 961.61064 | H23: 723.12964 | I23: 921.00276 | J23: 960.42382 | K23: 990.29651 | L23: 927.87515 | M23: 1033.6386 | N23: =SUM(B23:M23) -> 11315.722
A24: CPCL-NARIMANAM,TAMILNADU | B24: 0 | C24: 0 | D24: 0 | E24: 0 | F24: 0 | G24: 0 | H24: 0 | I24: 0 | J24: 0 | K24: 0 | L24: 0 | M24: 0 | N24: =SUM(B24:M24) -> 0
A25: CPCL-TOTAL | B25: =SUM(B23:B24) -> 904.19783 | C25: =SUM(C23:C24) -> 1005.4421 | D25: =SUM(D23:D24) -> 972.60578 | E25: =SUM(E23:E24) -> 975.06522 | F25: =SUM(F23:F24) -> 940.43378 | G25: =SUM(G23:G24) -> 961.61064 | H25: =SUM(H23:H24) -> 723.12964 | I25: =SUM(I23:I24) -> 921.00276 | ... M25: =SUM(M23:M24) -> 1033.6386 | N25: =SUM(B25:M25) -> 11315.722
A27: Bharat Petroleum Corporation Ltd. (BPCL)
A28: BPCL-MUMBAI, MAHARASHTRA | B28: 1301.7554 | C28: 1256.5507 | D28: 881.71101 | E28: 689.35759 | F28: 1246.6252 | G28: 1261.0326 | H28: 1306.8789 | I28: 1216.4536 | J28: 1344.114 | K28: 1390.2082 | L28: 1293.1171 | M28: 1358.2675 | N28: =SUM(B28:M28) -> 14546.072
A29: BPCL-KOCHI, KERALA | B29: 1314.1115 | C29: 1431.8539 | D29: 1363.8513 | E29: 1423.6467 | F29: 1377.3255 | G29: 1155.8843 | H29: 581.021 | I29: 1380.8235 | J29: 1506.6318 | K29: 1533.0759 | L29: 1406.5118 | M29: 1542.0189 | N29: =SUM(B29:M29) -> 16016.756
A30: BORL-BINA | B30: 684.49128 | C30: 675.72723 | D30: 649.81705 | E30: 586.53277 | F30: 412.2227 | G30: 650.73219 | H30: 705.15644 | I30: 691.93329 | J30: 712.60743 | K30: 678.7078 | L30: 657.04846 | M30: 735.71125 | N30: =SUM(B30:M30) -> 7840.6879
A31: BPCL-TOTAL | B31: =SUM(B28:B30) -> 3300.3582 | C31: =SUM(C28:C30) -> 3364.1319 | D31: =SUM(D28:D30) -> 2895.3793 | E31: =SUM(E28:E30) -> 2699.537 | F31: =SUM(F28:F30) -> 3036.1734 | G31: =SUM(G28:G30) -> 3067.649 | H31: =SUM(H28:H30) -> 2593.0563 | I31: =SUM(I28:I30) -> 3289.2104 | ... M31: =SUM(M28:M30) -> 3635.9977 | N31: =SUM(B31:M31) -> 38403.516
A32: NRL-NUMALIGARH, ASSAM | B32: 270.71994 | C32: 275.33742 | D32: 240.56195 | E32: 261.07462 | F32: 264.3258 | G32: 247.84873 | H32: 279.60915 | I32: 246.99792 | J32: 271.75837 | K32: 284.04529 | L32: 244.06159 | M32: 205.02356 | N32: =SUM(B32:M32) -> 3091.3643
A34: Oil & Natural Gas Corporation Ltd. (ONGC)
A35: ONGC-TATIPAKA,ANDHRA PRADESH | B35: 6.050573 | C35: 6.779479 | D35: 6.721341 | E35: 4.975766 | F35: 3.933622 | G35: 6.820562 | H35: 7.546718 | I35: 6.296553 | J35: 6.46411 | K35: 6.574067 | L35: 6.117798 | M35: 4.940589 | N35: =SUM(B35:M35) -> 73.221178
A36: MRPL-MANGALORE,KARNATAKA | B36: 1480.9694 | C36: 1415.2016 | D36: 1428.9668 | E36: 1428.3632 | F36: 1182.2085 | G36: 1329.6192 | H36: 1493.4728 | I36: 1461.5976 | J36: 1504.0463 | K36: 1496.5942 | L36: 1392.99 | M36: 1502.246 | N36: =SUM(B36:M36) -> 17116.275
A37: ONGC TOTAL | B37: =SUM(B35:B36) -> 1487.02 | C37: =SUM(C35:C36) -> 1421.9811 | D37: =SUM(D35:D36) -> 1435.6881 | E37: =SUM(E35:E36) -> 1433.3389 | F37: =SUM(F35:F36) -> 1186.1421 | G37: =SUM(G35:G36) -> 1336.4397 | H37: =SUM(H35:H36) -> 1501.0195 | I37: =SUM(I35:I36) -> 1467.8941 | ... M37: =SUM(M35:M36) -> 1507.1866 | N37: =SUM(B37:M37) -> 17189.497
A39: Hindustan Petroleum Corporation Ltd. (HPCL)
A40: HPCL-MUMBAI,MAHARASHTRA | B40: 731.48559 | C40: 844.05312 | D40: 851.69372 | E40: 876.48591 | F40: 766.90336 | G40: 786.46292 | H40: 761.39043 | I40: 820.12037 | J40: 850.56261 | K40: 837.69115 | L40: 803.64527 | M40: 873.82769 | N40: =SUM(B40:M40) -> 9804.3221
A41: HPCL-VISAKH,ANDHRA PRADESH | B41: 797.81385 | C41: 802.6652 | D41: 781.84231 | E41: 683.83095 | F41: 555.77781 | G41: 814.03873 | H41: 787.4904 | I41: 801.27917 | J41: 818.37609 | K41: 823.65055 | L41: 745.84023 | M41: 874.03102 | N41: =SUM(B41:M41) -> 9286.6363
A42: HMEL-GGSR, BATHINDA, PUNJAB | B42: 1039.859 | C42: 1111.185 | D42: 1078.477 | E42: 1109.489 | F42: 1019.695 | G42: 932.594 | H42: 1114.495 | I42: 978.049 | J42: 1116.441 | K42: 1116.623 | L42: 1008.015 | M42: 1110.379 | N42: =SUM(B42:M42) -> 12735.301
A43: HPCL-TOTAL | B43: =SUM(B40:B42) -> 2569.1584 | C43: =SUM(C40:C42) -> 2757.9033 | D43: =SUM(D40:D42) -> 2712.013 | E43: =SUM(E40:E42) -> 2669.8059 | F43: =SUM(F40:F42) -> 2342.3762 | G43: =SUM(G40:G42) -> 2533.0957 | H43: =SUM(H40:H42) -> 2663.3758 | I43: =SUM(I40:I42) -> 2599.4485 | ... M43: =SUM(M40:M42) -> 2858.2377 | N43: =SUM(B43:M43) -> 31826.259
A45: Reliance Industries Ltd. (RIL)
A46: RIL,JAMNAGAR,GUJARAT | B46: 3034.2691 | C46: 3123.937 | D46: 2953.7903 | E46: 2932.9641 | F46: 3029.9424 | G46: 2784.1079 | H46: 2931.6203 | I46: 2555.9159 | J46: 2840.8566 | K46: 2847.9967 | L46: 2575.9058 | M46: 2822.1633 | N46: =SUM(B46:M46) -> 34433.469
A47: RIL-(SEZ), JAMNAGAR,GUJARAT | B47: 2116.6447 | C47: 2547.2465 | D47: 2408.1138 | E47: 2549.4665 | F47: 2146.6436 | G47: 1838.7341 | H47: 1759.6395 | I47: 2677.7941 | J47: 2467.0466 | K47: 2542.8047 | L47: 2280.0351 | M47: 2537.5885 | N47: =SUM(B47:M47) -> 27871.758
A48: RIL TOTAL | B48: =SUM(B46:B47) -> 5150.9138 | C48: =SUM(C46:C47) -> 5671.1834 | D48: =SUM(D46:D47) -> 5361.9041 | E48: =SUM(E46:E47) -> 5482.4306 | F48: =SUM(F46:F47) -> 5176.586 | G48: =SUM(G46:G47) -> 4622.8419 | H48: =SUM(H46:H47) -> 4691.2598 | I48: =SUM(I46:I47) -> 5233.7099 | ... M48: =SUM(M46:M47) -> 5359.7519 | N48: =SUM(B48:M48) -> 62305.227
A50: NEL-VADINAR,GUJARAT | B50: 1659.9796 | C50: 1725.5137 | D50: 1679.6149 | E50: 1734.7981 | F50: 1750.8 | G50: 1692.1554 | H50: 1716.9611 | I50: 25.550887 | J50: 1712.0764 | K50: 1719.3741 | L50: 1568.22 | M50: 1707.4026 | N50: =SUM(B50:M50) -> 18692.447
A52: GRAND TOTAL | B52: =+B50+B48+B43+B37+B32+B31+B25+B20 -> 21579.611 | C52: =+C50+C48+C43+C37+C32+C31+C25+C20 -> 22643.899 | D52: =+D50+D48+D43+D37+D32+D31+D25+D20 -> 21574.57 | E52: =+E50+E48+E43+E37+E32+E31+E25+E20 -> 21423.24 | F52: =+F50+F48+F43+F37+F32+F31+F25+F20 -> 19533.697 | G52: =+G50+G48+G43+G37+G32+G31+G25+G20 -> 19549.918 | H52: =+H50+H48+H43+H37+H32+H31+H25+H20 -> 20413.629 | I52: =+I50+I48+I43+I37+I32+I31+I25+I20 -> 19580.024 | ... M52: =+M50+M48+M43+M37+M32+M31+M25+M20 -> 23003.61 | N52: =SUM(B52:M52) -> 255232.12
...

Sheet Monthwise 2021-22 
C2: Petroleum Planning & Analysis Cell
A7: 2021-22 | I7: ('000 Metric Tonnes)
A8: Crude Oil Processed by Refineries
A9: OIL COMPANIES | B9: APR | C9: MAY | D9: JUN | E9: JULY | F9: AUG | G9: SEP | H9: OCT | I9: NOV | J9: DEC | K9: JAN | L9: FEB | M9: MAR | N9: TOTAL
A10: Indian Oil Corporation Ltd.(IOCL)
A11: IOCL-BARAUNI,BIHAR | B11: 470.691 | C11: 532.638 | D11: 442.465 | E11: 569.13 | F11: 296.465 | G11: 56.143 | H11: 426.914 | I11: 479.053 | J11: 602.258 | K11: 618.634 | L11: 529.238 | M11: 596.034 | N11: =SUM(B11:M11) -> 5619.663
A12: IOCL-KOYALI, GUJARAT | B12: 997.518 | C12: 1042.141 | D12: 1072.183 | E12: 1101.533 | F12: 1089.672 | G12: 1005.097 | H12: 939.125 | I12: 1122.578 | J12: 1292.843 | K12: 1273.358 | L12: 1199.821 | M12: 1338.237 | N12: =SUM(B12:M12) -> 13474.106
A13: IOCL-HALDIA, WEST BENGAL | B13: 696.022 | C13: 624.18 | D13: 606.454 | E13: 643.554 | F13: 708.619 | G13: 641.511 | H13: 735.815 | I13: 707.577 | J13: 263.678 | K13: 301.494 | L13: 629.851 | M13: 746.704 | N13: =SUM(B13:M13) -> 7305.459
A14: IOCL-MATHURA, UTTAR PRADESH | B14: 818.797 | C14: 692.32 | D14: 698.183 | E14: 665.07 | F14: 642.705 | G14: 723.094 | H14: 854.415 | I14: 852.22 | J14: 765.781 | K14: 745.534 | L14: 780.543 | M14: 884.182 | N14: =SUM(B14:M14) -> 9122.844
A15: IOCL-PANIPAT, HARYANA | B15: 1321.738 | C15: 1155.541 | D15: 1212.604 | E15: 1343.217 | F15: 1149.576 | G15: 1085.751 | H15: 1315.118 | I15: 1339.984 | J15: 1297.873 | K15: 1220.906 | L15: 1121.636 | M15: 1284.91 | N15: =SUM(B15:M15) -> 14848.854
A16: IOCL-GUWAHATI,ASSAM | B16: 62.311 | C16: 0 | D16: 0 | E16: 0 | F16: 64.477 | G16: 76.51 | H16: 92.526 | I16: 83.173 | J16: 83.735 | K16: 92.14 | L16: 82.043 | M16: 93.3 | N16: =SUM(B16:M16) -> 730.215
A17: IOCL-DIGBOI,ASSAM | B17: 56.325 | C17: 61.436 | D17: 59.266 | E17: 60.361 | F17: 56.302 | G17: 59.857 | H17: 61.4 | I17: 60.881 | J17: 61.547 | K17: 59.463 | L17: 49.882 | M17: 61.109 | N17: =SUM(B17:M17) -> 707.829
A18: IOCL-BONGAIGAON,ASSAM | B18: 225.112 | C18: 226.698 | D18: 233.425 | E18: 226.209 | F18: 232.683 | G18: 218.975 | H18: 214.864 | I18: 217.363 | J18: 206.455 | K18: 207.441 | L18: 180.881 | M18: 248.394 | N18: =SUM(B18:M18) -> 2638.5
A19: IOCL-PARADIP,ODISHA | B19: 1331.795 | C19: 1045.384 | D19: 1033.756 | E19: 1058.56 | F19: 663.057 | G19: 838.479 | H19: 877.061 | I19: 1119.531 | J19: 1330.343 | K19: 1324.753 | L19: 1211.238 | M19: 1383.441 | N19: =SUM(B19:M19) -> 13217.398
A20: IOCL TOTAL | B20: =SUM(B11:B19) -> 5980.309 | C20: =SUM(C11:C19) -> 5380.338 | D20: =SUM(D11:D19) -> 5358.336 | E20: =SUM(E11:E19) -> 5667.634 | F20: =SUM(F11:F19) -> 4903.556 | G20: =SUM(G11:G19) -> 4705.417 | H20: =SUM(H11:H19) -> 5517.238 | I20: =SUM(I11:I19) -> 5982.36 | ... N20: =SUM(N11:N19) -> 67664.868
A22: Chennai Petroleum Corporation Ltd. (CPCL)
A23: CPCL-MANALI, TAMILNADU | B23: 759.79152 | C23: 629.16616 | D23: 645.55383 | E23: 818.55688 | F23: 629.06748 | G23: 496.7302 | H23: 500.22955 | I23: 815.5841 | J23: 840.13916 | K23: 915.0677 | L23: 928.45385 | M23: 1062.0789 | N23: =SUM(B23:M23) -> 9040.4193
A24: CPCL-NARIMANAM,TAMILNADU | B24: 0 | C24: 0 | D24: 0 | E24: 0 | F24: 0 | G24: 0 | H24: 0 | I24: 0 | J24: 0 | K24: 0 | L24: 0 | M24: 0 | N24: =SUM(B24:M24) -> 0
A25: CPCL-TOTAL | B25: =SUM(B23:B24) -> 759.79152 | C25: =SUM(C23:C24) -> 629.16616 | D25: =SUM(D23:D24) -> 645.55383 | E25: =SUM(E23:E24) -> 818.55688 | F25: =SUM(F23:F24) -> 629.06748 | G25: =SUM(G23:G24) -> 496.7302 | H25: =SUM(H23:H24) -> 500.22955 | I25: =SUM(I23:I24) -> 815.5841 | ... M25: =SUM(M23:M24) -> 1062.0789 | N25: =SUM(B25:M25) -> 9040.4193
A27: Bharat Petroleum Corporation Ltd. (BPCL)
A28: BPCL-MUMBAI, MAHARASHTRA | B28: 1225.2395 | C28: 1172.3891 | D28: 1029.4898 | E28: 1252.5908 | F28: 1285.5374 | G28: 956.85842 | H28: 1109.7976 | I28: 1293.8131 | J28: 1303.9317 | K28: 1302.5333 | L28: 1236.0939 | M28: 1268.2636 | N28: =SUM(B28:M28) -> 14436.538
A29: BPCL-KOCHI, KERALA | B29: 1363.4901 | C29: 910.20548 | D29: 1016.2637 | E29: 1086.5408 | F29: 1087.4829 | G29: 1338.1387 | H29: 1444.489 | I29: 1429.0038 | J29: 1359.8054 | K29: 1450.4296 | L29: 1394.0352 | M29: 1521.6241 | N29: =SUM(B29:M29) -> 15401.509
A30: BORL-BINA | B30: 647.53807 | C30: 518.89225 | D30: 424.87954 | E30: 622.71182 | F30: 598.09902 | G30: 578.61427 | H30: 658.44177 | I30: 683.79677 | J30: 656.83546 | K30: 721.98352 | L30: 594.40696 | M30: 703.55694 | N30: =SUM(B30:M30) -> 7409.7564
A31: BPCL-TOTAL | B31: =SUM(B28:B30) -> 3236.2677 | C31: =SUM(C28:C30) -> 2601.4869 | D31: =SUM(D28:D30) -> 2470.6331 | E31: =SUM(E28:E30) -> 2961.8434 | F31: =SUM(F28:F30) -> 2971.1193 | G31: =SUM(G28:G30) -> 2873.6114 | H31: =SUM(H28:H30) -> 3212.7284 | I31: =SUM(I28:I30) -> 3406.6137 | ... M31: =SUM(M28:M30) -> 3493.4447 | N31: =SUM(B31:M31) -> 37247.803
A32: NRL-NUMALIGARH, ASSAM | B32: 221.21643 | C32: 226.07787 | D32: 192.73218 | E32: 226.89474 | F32: 211.68782 | G32: 237.54492 | H32: 254.42491 | I32: 223.08894 | J32: 136.55063 | K32: 271.96545 | L32: 234.04479 | M32: 188.18056 | N32: =SUM(B32:M32) -> 2624.4092
A34: Oil & Natural Gas Corporation Ltd. (ONGC)
A35: ONGC-TATIPAKA,ANDHRA PRADESH | B35: 7.229394 | C35: 6.591119 | D35: 5.875409 | E35: 2.911995 | F35: 6.740592 | G35: 6.604453 | H35: 5.616575 | I35: 6.558709 | J35: 7.163875 | K35: 7.296336 | L35: 6.484306 | M35: 6.060001 | N35: =SUM(B35:M35) -> 75.132764
A36: MRPL-MANGALORE,KARNATAKA | B36: 1099.7921 | C36: 961.06293 | D36: 1009.6227 | E36: 1104.622 | F36: 1006.5704 | G36: 987.67497 | H36: 1462.9799 | I36: 1468.1118 | J36: 1433.9222 | K36: 1440.3249 | L36: 1392.274 | M36: 1503.7168 | N36: =SUM(B36:M36) -> 14870.675
A37: ONGC TOTAL | B37: =SUM(B35:B36) -> 1107.0214 | C37: =SUM(C35:C36) -> 967.65405 | D37: =SUM(D35:D36) -> 1015.4981 | E37: =SUM(E35:E36) -> 1107.534 | F37: =SUM(F35:F36) -> 1013.311 | G37: =SUM(G35:G36) -> 994.27942 | H37: =SUM(H35:H36) -> 1468.5965 | I37: =SUM(I35:I36) -> 1474.6705 | ... M37: =SUM(M35:M36) -> 1509.7768 | N37: =SUM(B37:M37) -> 14945.807
A39: Hindustan Petroleum Corporation Ltd. (HPCL)
A40: HPCL-MUMBAI,MAHARASHTRA | B40: 41.290164 | C40: 118.74334 | D40: 304.13227 | E40: 319.2429 | F40: 298.83914 | G40: 411.27388 | H40: 534.76957 | I40: 545.2006 | J40: 673.92315 | K40: 852.2013 | L40: 747.54982 | M40: 710.68587 | N40: =SUM(B40:M40) -> 5557.852
A41: HPCL-VISAKH,ANDHRA PRADESH | B41: 826.13667 | C41: 736.55728 | D41: 481.14643 | E41: 480.39823 | F41: 479.1408 | G41: 545.88692 | H41: 853.28815 | I41: 819.41524 | J41: 809.25573 | K41: 792.59827 | L41: 761.39534 | M41: 824.61103 | N41: =SUM(B41:M41) -> 8409.8301
A42: HMEL-GGSR, BATHINDA, PUNJAB | B42: 1058.897 | C42: 1102.4 | D42: 1062.922 | E42: 1098.169 | F42: 1111.834 | G42: 1079.385 | H42: 1113.14 | I42: 1080.063 | J42: 1117.721 | K42: 1099.938 | L42: 1009.915 | M42: 1092.369 | N42: =SUM(B42:M42) -> 13026.753
A43: HPCL-TOTAL | B43: =SUM(B40:B42) -> 1926.3238 | C43: =SUM(C40:C42) -> 1957.7006 | D43: =SUM(D40:D42) -> 1848.2007 | E43: =SUM(E40:E42) -> 1897.8101 | F43: =SUM(F40:F42) -> 1889.8139 | G43: =SUM(G40:G42) -> 2036.5458 | H43: =SUM(H40:H42) -> 2501.1977 | I43: =SUM(I40:I42) -> 2444.6788 | ... M43: =SUM(M40:M42) -> 2627.6659 | N43: =SUM(B43:M43) -> 26994.435
A45: Reliance Industries Ltd. (RIL)
A46: RIL,JAMNAGAR,GUJARAT | B46: 2772.5458 | C46: 2837.0352 | D46: 2689.845 | E46: 2742.687 | F46: 2872.5195 | G46: 2841.1487 | H46: 3109.8283 | I46: 2997.139 | J46: 3019.2727 | K46: 3042.2195 | L46: 2777.2966 | M46: 3055.5301 | N46: =SUM(B46:M46) -> 34757.067
A47: RIL-(SEZ), JAMNAGAR,GUJARAT | B47: 2248.4463 | C47: 2678.1419 | D47: 2529.5068 | E47: 2283.9305 | F47: 2237.0975 | G47: 2361.4243 | H47: 2644.2205 | I47: 2450.8112 | J47: 2509.578 | K47: 2234.8321 | L47: 2012.7944 | M47: 2073.641 | N47: =SUM(B47:M47) -> 28264.424
A48: RIL TOTAL | B48: =SUM(B46:B47) -> 5020.9921 | C48: =SUM(C46:C47) -> 5515.1771 | D48: =SUM(D46:D47) -> 5219.3519 | E48: =SUM(E46:E47) -> 5026.6174 | F48: =SUM(F46:F47) -> 5109.617 | G48: =SUM(G46:G47) -> 5202.573 | H48: =SUM(H46:H47) -> 5754.0488 | I48: =SUM(I46:I47) -> 5447.9502 | ... M48: =SUM(M46:M47) -> 5129.171 | N48: =SUM(B48:M48) -> 63021.492
A50: NEL-VADINAR,GUJARAT | B50: 1632.7803 | C50: 1692.4649 | D50: 1649.7648 | E50: 1676.7377 | F50: 1710.4047 | G50: 1667.7173 | H50: 1749.1707 | I50: 1688.4711 | J50: 1710.1098 | K50: 1733.4432 | L50: 1563.1473 | M50: 1690.1996 | N50: =SUM(B50:M50) -> 20164.411
A52: GRAND TOTAL | B52: =+B50+B48+B43+B37+B32+B31+B25+B20 -> 19884.702 | C52: =+C50+C48+C43+C37+C32+C31+C25+C20 -> 18970.066 | D52: =+D50+D48+D43+D37+D32+D31+D25+D20 -> 18400.071 | E52: =+E50+E48+E43+E37+E32+E31+E25+E20 -> 19383.628 | F52: =+F50+F48+F43+F37+F32+F31+F25+F20 -> 18438.577 | G52: =+G50+G48+G43+G37+G32+G31+G25+G20 -> 18214.419 | H52: =+H50+H48+H43+H37+H32+H31+H25+H20 -> 20957.634 | I52: =+I50+I48+I43+I37+I32+I31+I25+I20 -> 21483.417 | ... M52: =+M50+M48+M43+M37+M32+M31+M25+M20 -> 22336.828 | N52: =SUM(B52:M52) -> 241703.65
...

Sheet Monthwise 2020-21
C2: Petroleum Planning & Analysis Cell
A7: 2020-21 | I7: ('000 Metric Tonnes)
A8: Crude Oil Processed by Refineries
A9: OIL COMPANIES | B9: APR | C9: MAY | D9: JUN | E9: JULY | F9: AUG | G9: SEP | H9: OCT | I9: NOV | J9: DEC | K9: JAN | L9: FEB | M9: MAR | N9: TOTAL
A10: Indian Oil Corporation Ltd.(IOCL)
A11: IOCL-BARAUNI,BIHAR | B11: 246.526 | C11: 337.415 | D11: 512.165 | E11: 436.624 | F11: 317.716 | G11: 375.661 | H11: 435.152 | I11: 578.86 | J11: 552.791 | K11: 589.161 | L11: 518.24 | M11: 568.908 | N11: =SUM(B11:M11) -> 5469.219
A12: IOCL-KOYALI, GUJARAT | B12: 578.306 | C12: 769.435 | D12: 1040.898 | E12: 1091.864 | F12: 834.438 | G12: 899.179 | H12: 1048.926 | I12: 1123.536 | J12: 1173.262 | K12: 1186.5 | L12: 912.28 | M12: 944.427 | N12: =SUM(B12:M12) -> 11603.051
A13: IOCL-HALDIA, WEST BENGAL | B13: 305.299 | C13: 319.252 | D13: 532.996 | E13: 580.173 | F13: 562.179 | G13: 440.15 | H13: 585.297 | I13: 679.582 | J13: 708.659 | K13: 723.079 | L13: 657.238 | M13: 664.607 | N13: =SUM(B13:M13) -> 6758.511
A14: IOCL-MATHURA, UTTAR PRADESH | B14: 505.715 | C14: 730.123 | D14: 768.853 | E14: 753.623 | F14: 640.869 | G14: 614.664 | H14: 708.83 | I14: 795.551 | J14: 870.591 | K14: 893.213 | L14: 790.364 | M14: 853.399 | N14: =SUM(B14:M14) -> 8925.795
A15: IOCL-PANIPAT, HARYANA | B15: 457.242 | C15: 919.34 | D15: 1172.98 | E15: 1115.315 | F15: 976.505 | G15: 1025.371 | H15: 1237.21 | I15: 1359.317 | J15: 1359.048 | K15: 1320.827 | L15: 1046.65 | M15: 1191.518 | N15: =SUM(B15:M15) -> 13181.323
A16: IOCL-GUWAHATI,ASSAM | B16: 0 | C16: 23.551 | D16: 64.006 | E16: 87.05 | F16: 89.198 | G16: 74.933 | H16: 84.444 | I16: 82.691 | J16: 84.344 | K16: 90.316 | L16: 79.684 | M16: 89.021 | N16: =SUM(B16:M16) -> 849.238
A17: IOCL-DIGBOI,ASSAM | B17: 53.563 | C17: 56.229 | D17: 61.049 | E17: 51.232 | F17: 56.047 | G17: 45.892 | H17: 61.006 | I17: 58.644 | J17: 57.945 | K17: 57.653 | L17: 22.416 | M17: 23.434 | N17: =SUM(B17:M17) -> 605.11
A18: IOCL-BONGAIGAON,ASSAM | B18: 174.217 | C18: 196.199 | D18: 192.625 | E18: 222.436 | F18: 206.294 | G18: 188.809 | H18: 222.236 | I18: 206.413 | J18: 204.396 | K18: 210.933 | L18: 195.934 | M18: 229.969 | N18: =SUM(B18:M18) -> 2450.461
A19: IOCL-PARADIP,ODISHA | B19: 725.261 | C19: 959.357 | D19: 1227.305 | E19: 1024.685 | F19: 266.397 | G19: 992.057 | H19: 1278.956 | I19: 1325.084 | J19: 976.53 | K19: 1206.436 | L19: 1164.255 | M19: 1361.616 | N19: =SUM(B19:M19) -> 12507.939
A20: IOCL TOTAL | B20: =SUM(B11:B19) -> 3046.129 | C20: =SUM(C11:C19) -> 4310.901 | D20: =SUM(D11:D19) -> 5572.877 | E20: =SUM(E11:E19) -> 5363.002 | F20: =SUM(F11:F19) -> 3949.643 | G20: =SUM(G11:G19) -> 4656.716 | H20: =SUM(H11:H19) -> 5662.057 | I20: =SUM(I11:I19) -> 6209.678 | ... N20: =SUM(N11:N19) -> 62350.647
A22: Chennai Petroleum Corporation Ltd. (CPCL)
A23: CPCL-MANALI, TAMILNADU | B23: 307.60443 | C23: 441.20078 | D23: 579.15932 | E23: 723.80293 | F23: 561.67691 | G23: 769.86892 | H23: 725.2619 | I23: 729.44649 | J23: 766.26665 | K23: 917.46453 | L23: 757.59894 | M23: 963.53868 | N23: =SUM(B23:M23) -> 8242.8905
A24: CPCL-NARIMANAM,TAMILNADU | B24: 0 | C24: 0 | D24: 0 | E24: 0 | F24: 0 | G24: 0 | H24: 0 | I24: 0 | J24: 0 | K24: 0 | L24: 0 | M24: 0 | N24: =SUM(B24:M24) -> 0
A25: CPCL-TOTAL | B25: =SUM(B23:B24) -> 307.60443 | C25: =SUM(C23:C24) -> 441.20078 | D25: =SUM(D23:D24) -> 579.15932 | E25: =SUM(E23:E24) -> 723.80293 | F25: =SUM(F23:F24) -> 561.67691 | G25: =SUM(G23:G24) -> 769.86892 | H25: =SUM(H23:H24) -> 725.2619 | I25: =SUM(I23:I24) -> 729.44649 | ... M25: =SUM(M23:M24) -> 963.53868 | N25: =SUM(B25:M25) -> 8242.8905
A27: Bharat Petroleum Corporation Ltd. (BPCL)
A28: BPCL-MUMBAI, MAHARASHTRA | B28: 768.43205 | C28: 907.02951 | D28: 971.80884 | E28: 1096.853 | F28: 827.69401 | G28: 909.3861 | H28: 1051.219 | I28: 1247.3111 | J28: 1200.474 | K28: 1320.1734 | L28: 1263.765 | M28: 1376.4491 | N28: =SUM(B28:M28) -> 12940.595
A29: BPCL-KOCHI, KERALA | B29: 815.3295 | C29: 676.42608 | D29: 931.42591 | E29: 843.74463 | F29: 935.67298 | G29: 980.36738 | H29: 1065.7302 | I29: 1337.3942 | J29: 1328.8164 | K29: 1573.1396 | L29: 1410.3965 | M29: 1383.3507 | N29: =SUM(B29:M29) -> 13281.794
A30: BORL-BINA | B30: 332.28393 | C30: 440.07313 | D30: 387.19589 | E30: 411.47019 | F30: 450.86828 | G30: 489.28364 | H30: 561.14166 | I30: 593.92538 | J30: 625.34321 | K30: 694.44121 | L30: 601.47248 | M30: 602.13099 | N30: =SUM(B30:M30) -> 6189.63
A31: NRL-NUMALIGARH, ASSAM | B31: 169.73277 | C31: 205.76543 | D31: 249.71455 | E31: 219.30183 | F31: 225.72064 | G31: 198.14477 | H31: 232.22806 | I31: 230.11692 | J31: 259.78027 | K31: 248.84312 | L31: 227.10363 | M31: 240.90137 | N31: =SUM(B31:M31) -> 2707.3534
A32: BPCL-TOTAL | B32: =SUM(B28:B31) -> 2085.7782 | C32: =SUM(C28:C31) -> 2229.2941 | D32: =SUM(D28:D31) -> 2540.1452 | E32: =SUM(E28:E31) -> 2571.3697 | F32: =SUM(F28:F31) -> 2439.9559 | G32: =SUM(G28:G31) -> 2577.1819 | H32: =SUM(H28:H31) -> 2910.3188 | I32: =SUM(I28:I31) -> 3408.7476 | ... M32: =SUM(M28:M31) -> 3602.8321 | N32: =SUM(B32:M32) -> 35119.372
A34: Oil & Natural Gas Corporation Ltd. (ONGC)
A35: ONGC-TATIPAKA,ANDHRA PRADESH | B35: 1.917599 | C35: 6.292385 | D35: 7.412129 | E35: 7.266961 | F35: 7.426 | G35: 7.288859 | H35: 7.098053 | I35: 6.692406 | J35: 7.10751 | K35: 7.559351 | L35: 7.207295 | M35: 7.721329 | N35: =SUM(B35:M35) -> 80.989877
A36: MRPL-MANGALORE,KARNATAKA | B36: 670.64642 | C36: 565.893 | D36: 626.9512 | E36: 765.711 | F36: 905.22121 | G36: 812.518 | H36: 731.015 | I36: 1011.4409 | J36: 1306.5627 | K36: 1419.8366 | L36: 1297.3569 | M36: 1361.3944 | N36: =SUM(B36:M36) -> 11474.547
A37: ONGC TOTAL | B37: =SUM(B35:B36) -> 672.56402 | C37: =SUM(C35:C36) -> 572.18538 | D37: =SUM(D35:D36) -> 634.36333 | E37: =SUM(E35:E36) -> 772.97796 | F37: =SUM(F35:F36) -> 912.64721 | G37: =SUM(G35:G36) -> 819.80686 | H37: =SUM(H35:H36) -> 738.11305 | I37: =SUM(I35:I36) -> 1018.1333 | ... M37: =SUM(M35:M36) -> 1369.1157 | N37: =SUM(B37:M37) -> 11555.537
A39: Hindustan Petroleum Corporation Ltd. (HPCL)
A40: HPCL-MUMBAI,MAHARASHTRA | B40: 549.48409 | C40: 524.54383 | D40: 653.90868 | E40: 637.23881 | F40: 658.21358 | G40: 670.22153 | H40: 495.89462 | I40: 611.71652 | J40: 577.89486 | K40: 638.70285 | L40: 641.81962 | M40: 714.56907 | N40: =SUM(B40:M40) -> 7374.2081
A41: HPCL-VISAKH,ANDHRA PRADESH | B41: 774.48944 | C41: 742.62523 | D41: 725.23776 | E41: 717.53046 | F41: 651.49381 | G41: 728.15618 | H41: 792.94546 | I41: 807.51891 | J41: 706.58101 | K41: 800.23725 | L41: 737.10237 | M41: 866.55462 | N41: =SUM(B41:M41) -> 9050.4725
A42: HMEL-GGSR, BATHINDA, PUNJAB | B42: 592.85 | C42: 653.139 | D42: 784.708 | E42: 1035.451 | F42: 1047.468 | G42: 1015.784 | H42: 1038.175 | I42: 1037.997 | J42: 1026.716 | K42: 801.292 | L42: 13.369 | M42: 1025.053 | N42: =SUM(B42:M42) -> 10072.002
A43: HPCL-TOTAL | B43: =SUM(B40:B42) -> 1916.8235 | C43: =SUM(C40:C42) -> 1920.3081 | D43: =SUM(D40:D42) -> 2163.8544 | E43: =SUM(E40:E42) -> 2390.2203 | F43: =SUM(F40:F42) -> 2357.1754 | G43: =SUM(G40:G42) -> 2414.1617 | H43: =SUM(H40:H42) -> 2327.0151 | I43: =SUM(I40:I42) -> 2457.2324 | ... M43: =SUM(M40:M42) -> 2606.1767 | N43: =SUM(B43:M43) -> 26496.683
A45: Reliance Industries Ltd. (RIL)
